Workbook

Sheet Dashboard
B2: Financial Dashboard
B4: Year | C4: =Principal!C3 -> 2003 | D4: =Principal!D3 -> 2004 | E4: =Principal!E3 -> 2005 | F4: =Principal!F3 -> 2006 | G4: =Principal!G3 -> 2007 | H4: =Principal!H3 -> 2008 | I4: =Principal!I3 -> 2009 | J4: =Principal!J3 -> 2010 | ... AA4: =Principal!AA3 -> 2027
B5: Total Income | C5: =Principal!C13 -> 25595 | D5: =Principal!D13 -> 29655 | E5: =Principal!E13 -> 38875 | F5: =Principal!F13 -> 34850 | G5: =Principal!G13 -> 26575 | H5: =Principal!H13 -> 26700 | I5: =Principal!I13 -> 56950 | J5: =Principal!J13 -> 41080 | ... AA5: =Principal!AA13 -> 0
B6: Total Expenses | C6: =Principal!C51 -> 21996 | D6: =Principal!D51 -> 19294 | E6: =Principal!E51 -> 27015 | F6: =Principal!F51 -> 23585 | G6: =Principal!G51 -> 23200 | H6: =Principal!H51 -> 29780 | I6: =Principal!I51 -> 44265 | J6: =Principal!J51 -> 39830 | ... AA6: =Principal!AA51 -> 0
B7: Net Savings | C7: =Principal!C58 -> 716 | D7: =Principal!D58 -> 6158 | E7: =Principal!E58 -> 11033 | F7: =Principal!F58 -> 10435 | G7: =Principal!G58 -> 2825 | H7: =Principal!H58 -> -5940 | I7: =Principal!I58 -> 10935 | J7: =Principal!J58 -> 1250 | ... AA7: =Principal!AA58 -> 0
B9: Savings Margin (%) | C9: =IF(C5=0, 0, C7/C5) -> 0.027974214 | D9: =IF(D5=0, 0, D7/D5) -> 0.2076547 | E9: =IF(E5=0, 0, E7/E5) -> 0.28380707 | F9: =IF(F5=0, 0, F7/F5) -> 0.29942611 | G9: =IF(G5=0, 0, G7/G5) -> 0.10630292 | H9: =IF(H5=0, 0, H7/H5) -> -0.22247191 | I9: =IF(I5=0, 0, I7/I5) -> 0.19201054 | J9: =IF(J5=0, 0, J7/J5) -> 0.030428432 | ... AA9: =IF(AA5=0, 0, AA7/AA5) -> 0

Sheet Info
B2: FINANZAS DOMÉSTICAS 2002 - 2026
AD8: =COUNTA(D9:AC9) -> 25 | AE8: Años
D9: 2002 | E9: 2003 | F9: 2004 | G9: 2005 | H9: 2006 | I9: 2007 | J9: 2008 | K9: 2009 | L9: 2010 | M9: 2011 | N9: 2012 | O9: 2013 | P9: 2014 | Q9: 2015 | R9: 2016 | S9: 2017 | T9: 2018 | U9: 2019 | V9: 2020 | W9: 2021 | X9: 2022 | Y9: 2023 | Z9: 2024 | AA9: 2025 | AB9: 2026 | AD9: TOTALES
D10: 14990 | E10: 25595 | F10: 29655 | G10: 38875 | H10: 34850 | I10: 26500 | J10: 26700 | K10: 56550 | L10: 41080 | M10: 19720 | N10: 24700 | O10: 25875 | P10: 27865 | Q10: 29035 | R10: 31595 | S10: 31265 | T10: 31760 | U10: 31575 | V10: 32245 | W10: 35815 | X10: 37330 | Y10: 37980 | Z10: 44150 | AA10: 46200 | AC10: Ingresos | AD10: =SUM(D10:AA10) -> 781905 | AE10: (netos)
D11: 11525 | E11: 24880 | F11: 23500 | G11: 27850 | H11: 23800 | I11: 23500 | J11: 32650 | K11: 46550 | L11: 39850 | M11: 26570 | N11: 29500 | O11: 30150 | P11: 33090 | Q11: 24190 | R11: 36075 | S11: 27750 | T11: 34135 | U11: 29070 | V11: 27695 | W11: 31025 | X11: 38670 | Y11: 46435 | Z11: 48705 | AA11: 48600 | AC11: Gastos | AD11: =SUM(D11:AA11) -> 765765
D13: =D10-D11 -> 3465 | E13: =E10-E11 -> 715 | F13: =F10-F11 -> 6155 | G13: =G10-G11 -> 11025 | H13: =H10-H11 -> 11050 | I13: =I10-I11 -> 3000 | J13: =J10-J11 -> -5950 | K13: =K10-K11 -> 10000 | ... AA13: =AA10-AA11 -> -2400 | AC13: Resto | AD13: =SUM(D13:AA13) -> 16140
D15: SVS | E15: SVS | F15: SVS | G15: Trak | H15: Olivia | I15: MIPS | J15: MIPS | K15: MIPS | L15: Novartis
F16: Trak | G16: Olivia | H16: MIPS | K16: Novartis | L16: Nexus
D37: 2022 | E37: 2023 | G37: 2023 | H37: 2024 | J37: 2024 | K37: 2025 | M37: 2025 | N37: 2026 | P37: 2026 | Q37: 2027
D38: Sept | E38: Ene | G38: Sept | H38: Ene | J38: Sept | K38: Ene | M38: Sept | N38: Ene | P38: Sept | Q38: Ene
C39: Cuenta Corriente | D39: 46000 | E39: 47000 | F39: =E39/$E$46 -> 0.68814056 | G39: 40000 | H39: 39450 | I39: =H39/$H$46 -> 0.5571247 | J39: 36700 | K39: 35575 | L39: =K39/$K$46 -> 0.45530172 | M39: 35710 | N39: 31200 | O39: =N39/$N$46 -> 0.3604228
C40: Cuenta BBVA | D40: 1600 | E40: 650 | F40: =E40/$E$46 -> 0.0095168375 | G40: 405 | H40: 395 | I40: =H40/$H$46 -> 0.0055783081 | J40: 540 | K40: 750 | L40: =K40/$K$46 -> 0.0095987714 | M40: 445 | N40: 500 | O40: =N40/$N$46 -> 0.0057760065
C41: ETFs y acciones(*) | D41: 1000 | E41: 2000 | F41: =E41/$E$46 -> 0.029282577 | G41: 6150 | H41: 8130 | I41: =H41/$H$46 -> 0.11481429 | J41: 11385 | K41: 12575 | L41: =K41/$K$46 -> 0.1609394 | M41: =M48+M49 -> 17915 | N41: 20430 | O41: =N41/$N$46 -> 0.23600762 | R41: (DeGiro + BrokerNow)
C42: Fondo BBVA | D42: 1500 | E42: 2700 | F42: =E42/$E$46 -> 0.039531479 | G42: 3585 | H42: 4195 | I42: =H42/$H$46 -> 0.059243045 | J42: 5315 | K42: 5500 | L42: =K42/$K$46 -> 0.07039099 | M42: 6400 | N42: 6900 | O42: =N42/$N$46 -> 0.079708889 | R42: (BBVA Futuro Sostenible ISR FI)
C43: PP La Caixa | D43: 15650 | E43: 14500 | F43: =E43/$E$46 -> 0.21229868 | G43: 15950 | H43: 16000 | I43: =H43/$H$46 -> 0.22595679 | J43: 18150 | K43: 19125 | L43: =K43/$K$46 -> 0.24476867 | M43: 19050 | N43: 20150 | O43: =N43/$N$46 -> 0.23277306 | R43: (CABK Tendencias Renta Variable)
C44: PPE Santander | D44: 925 | E44: 1450 | F44: =E44/$E$46 -> 0.021229868 | G44: 2140 | H44: 2640 | I44: =H44/$H$46 -> 0.03728287 | J44: 3985 | K44: 4610 | L44: =K44/$K$46 -> 0.059000448 | M44: 5900 | N44: 7385 | O44: =N44/$N$46 -> 0.085311616
C46: TOTAL | D46: =SUM(D39:D45) -> 66675 | E46: =SUM(E39:E45) -> 68300 | G46: =SUM(G39:G45) -> 68230 | H46: =SUM(H39:H45) -> 70810 | J46: =SUM(J39:J45) -> 76075 | K46: =SUM(K39:K45) -> 78135 | M46: =SUM(M39:M45) -> 85420 | N46: =SUM(N39:N45) -> 86565
D48: (*) | E48: DeGiro, BrokerNow | L48: BrokerNow | M48: 5810 | N48: 7215
L49: DeGiro | M49: 12105 | N49: 13215

Sheet Historico
C4: Ahorro | D4: CC | E4: Total
B5: 39873 | C5: 21350 | D5: 17700 | E5: =C5+D5 -> 39050
B6: 39965 | C6: 21450 | D6: 9700 | E6: =C6+D6 -> 31150 | F6: minimo
B7: 40026 | C7: 21450 | D7: 22200 | E7: =C7+D7 -> 43650
B8: 40118 | C8: 21450 | D8: 22500 | E8: =C8+D8 -> 43950
B9: 40210 | C9: 21450 | D9: 27800 | E9: =C9+D9 -> 49250
B10: 40269 | C10: 21450 | D10: 29700 | E10: =C10+D10 -> 51150
B11: 40330 | C11: 21450 | D11: 30700 | E11: =C11+D11 -> 52150
B12: 40422 | C12: 21450 | D12: 30600 | E12: =C12+D12 -> 52050
B13: 40513 | C13: 21460 | D13: 30600 | E13: =C13+D13 -> 52060
B14: 40603 | C14: 21470 | D14: 27600 | E14: =C14+D14 -> 49070
B15: 40695 | C15: 21470 | D15: 25000 | E15: =C15+D15 -> 46470
B16: 40787 | C16: 21475 | D16: 24000 | E16: =C16+D16 -> 45475
B17: 40878 | C17: 21475 | D17: 23000 | E17: =C17+D17 -> 44475
B18: 40969 | C18: 21480 | D18: 18000 | E18: =C18+D18 -> 39480
... B36: 42614 | C36: 14500 | D36: 17500 | E36: =C36+D36 -> 32000
B37: 42705 | C37: 12225 | D37: 25000 | E37: =C37+D37 -> 37225 | G37: A partir de 2016 Ahorro = SIAL + Plazo Fijo + Plan Pensiones
B38: 42795 | C38: 12350 | D38: 25000 | E38: =C38+D38 -> 37350 | N38: A partir del 2016 Ahorro = SIAL + Deposito + PlanJubilacion
B39: 42887 | C39: 13225 | D39: 27000 | E39: =C39+D39 -> 40225
B40: 42979 | C40: 13750 | D40: 27500 | E40: =C40+D40 -> 41250 | Y40: Años
B41: 43070 | C41: 14000 | D41: 29000 | E41: =C41+D41 -> 43000 | I41: 2025 | J41: 2024 | K41: 2023 | L41: 2022 | M41: 2021 | N41: 2020 | O41: 2019 | P41: 2018 | Q41: 2017 | R41: 2016 | S41: 2015 | T41: 2014 | U41: 2013 | V41: 2012 | W41: 2011 | Y41: =COUNTA(I41:X41) -> 15
B42: 43160 | C42: 16250 | D42: 26000 | E42: =C42+D42 -> 42250
B43: 43252 | C43: 16750 | D43: 28000 | E43: =C43+D43 -> 44750 | X43: TOTALES
B44: 43344 | C44: 17000 | D44: 28000 | E44: =C44+D44 -> 45000 | G44: Total Ingresos | J44: 44150 | K44: 37980 | L44: 37330 | M44: 35815 | N44: 32245 | O44: 31575 | P44: 31760 | Q44: 31130 | R44: 31625 | S44: 29035 | T44: 26300 | U44: 25875 | V44: 25750 | W44: 19720 | X44: =SUM(I44:W44) -> 440290 | Y44: TOTAL
B45: 43435 | C45: 19250 | D45: 25000 | E45: =C45+D45 -> 44250 | H45: Hacienda | L45: 575
B46: 43466 | C46: 19600 | D46: 24100 | E46: =C46+D46 -> 43700 | G46: Ahorro e Inversion | J46: 3048 | K46: 4345 | X46: =SUM(I46:W46) -> 7393
B47: 43525 | C47: 20200 | D47: 22500 | E47: =C47+D47 -> 42700 | G47: Automovil
B48: 43586 | C48: 21000 | D48: 23000 | E48: =C48+D48 -> 44000 | H48: Compra/Renting | J48: 2650 | K48: 11360 | L48: 400 | M48: 2350 | N48: 2175 | O48: 3450 | P48: 0 | Q48: 0 | R48: 10600 | S48: 0 | T48: 0 | U48: 9300 | V48: 0 | W48: 0 | X48: =SUM(I48:W48) -> 42285 | Y48: COCHE
B49: 43647 | C49: 21100 | D49: 25500 | E49: =C49+D49 -> 46600 | H49: Combustible | J49: 370 | K49: 220 | L49: 175 | M49: 60 | N49: 245 | O49: 950 | P49: 900 | Q49: 1075 | R49: 950 | S49: 1000 | T49: 950 | U49: 1450 | V49: 1430 | W49: 650 | X49: =SUM(I49:W49) -> 10425
B50: 43709 | C50: 21500 | D50: 24500 | E50: =C50+D50 -> 46000 | H50: Impuestos | J50: 70 | K50: 290 | L50: 70 | M50: 150 | N50: 70 | O50: 70 | P50: 70 | Q50: 70 | R50: 125 | S50: 70 | T50: 70 | U50: 70 | V50: 90 | W50: 70 | X50: =SUM(I50:W50) -> 1355
B51: 43770 | C51: 22100 | D51: 25500 | E51: =C51+D51 -> 47600 | H51: Mantenimiento | J51: 15 | K51: 20 | L51: 30 | M51: 165 | N51: 0 | O51: 155 | P51: 525 | Q51: 165 | R51: 0 | S51: 255 | T51: 270 | U51: 85 | V51: 360 | W51: 100 | X51: =SUM(I51:W51) -> 2145
B52: 43800 | C52: 22200 | D52: 28000 | E52: =C52+D52 -> 50200 | H52: Parking,Peajes | J52: 0 | K52: 35 | L52: 45 | M52: 0 | N52: 75 | O52: 100 | P52: 300 | Q52: 160 | R52: 150 | S52: 50 | T52: 220 | U52: 70 | V52: 50 | W52: 25 | X52: =SUM(I52:W52) -> 1280
B53: 43831 | C53: 22650 | D53: 27000 | E53: =C53+D53 -> 49650 | G53: Dietas | J53: 5475 | K53: 4550 | L53: 3840 | M53: 3655 | N53: 2925 | O53: 2150 | P53: 1770 | Q53: 2475 | R53: 1815 | S53: 1425 | T53: 1275 | U53: 1100 | V53: 1665 | W53: 2700 | X53: =SUM(I53:W53) -> 36820 | Y53: SUPER
B54: 43891 | C54: 22650 | D54: 26500 | E54: =C54+D54 -> 49150 | G54: Gimnasios y ropa dep | J54: 685 | K54: 450 | L54: 285 | M54: 205 | N54: 335 | O54: 375 | P54: 300 | Q54: 325 | R54: 375 | S54: 350 | T54: 875 | U54: 605 | V54: 775 | W54: 625 | X54: =SUM(I54:W54) -> 6565 | Y54: DEPORTE
B55: 43952 | C55: 22500 | D55: 28500 | E55: =C55+D55 -> 51000 | H55: Libros, colecciones, papeleria | K55: 5 | L55: 5 | M55: 280 | N55: 280 | O55: 615 | P55: 600 | Q55: 725 | R55: 675 | S55: 325 | T55: 555 | U55: 110 | V55: 210 | W55: 1000 | X55: =SUM(I55:W55) -> 5385
B56: 44013 | C56: 23000 | D56: 28500 | E56: =C56+D56 -> 51500 | G56: Agua, Luz, Gas | J56: 1245 | K56: 1095 | L56: 1195 | M56: 1345 | N56: 1360 | O56: 1350 | P56: 1200 | Q56: 1150 | R56: 1475 | S56: 250 | T56: 1125 | U56: 900 | V56: 900 | W56: 860 | X56: =SUM(I56:W56) -> 15450 | Y56: AGUA LUZ GAS
B57: 44075 | C57: 24000 | D57: 29000 | E57: =C57+D57 -> 53000 | G57: Telefonía | J57: 470 | K57: 465 | L57: 420 | M57: 420 | N57: 410 | O57: 370 | P57: 575 | Q57: 525 | R57: 300 | S57: 775 | T57: 575 | U57: 610 | V57: 855 | W57: 1270 | X57: =SUM(I57:W57) -> 8040 | Y57: TELECO
B58: 44105 | C58: 23850 | D58: 31500 | E58: =C58+D58 -> 55350 | G58: Alquiler | J58: 10740 | K58: 10440 | L58: 9940 | M58: 9840 | N58: 9675 | O58: 9840 | P58: 9550 | Q58: 9125 | R58: 8900 | S58: 8900 | T58: 11225 | U58: 8650 | V58: 12000 | W58: 8570 | X58: =SUM(I58:W58) -> 137395 | Y58: ALQUILER
B59: 44166 | C59: 24750 | D59: 32500 | E59: =C59+D59 -> 57250 | G59: Hogar y vestuario | J59: 2280 | K59: 5 | L59: 385 | M59: 1970 | N59: 320 | O59: 475 | P59: 450 | Q59: 275 | R59: 1550 | S59: 575 | T59: 4000 | U59: 600 | V59: 4800 | W59: 700 | X59: =SUM(I59:W59) -> 18385 | Y59: HOGAR
B60: 44197 | C60: 26000 | D60: 36000 | E60: =C60+D60 -> 62000 | G60: Niños | J60: 875 | K60: 2445 | L60: 2845 | M60: 2780 | N60: 800 | O60: 1425 | P60: 1650 | Q60: 975 | R60: 1015 | S60: 500 | T60: 400 | U60: 250 | X60: =SUM(I60:W60) -> 15960 | Y60: NIÑOS
...

Sheet WIP
B5: Año ▾ | C5: Mes | D5: Ingresos | E5: Gastos | F5: Diferencia | H5: Año | I5: Mes | J5: Ingresos | K5: Gastos | L5: Diferencia
B6: 2022 | C6: Enero | D6: 4085 | E6: 4045 | F6: 40 | H6: 2023 | I6: Enero | J6: 3900 | K6: 3495 | L6: 405
B7: 2022 | C7: Febrero | D7: 1885 | E7: 6470 | F7: -4585 | H7: 2023 | I7: Febrero | J7: 1790 | K7: 10430 | L7: -8640
B8: 2022 | C8: Marzo | D8: 1890 | E8: 1880 | F8: 10 | H8: 2023 | I8: Marzo | J8: 1770 | K8: 1825 | L8: -55
B9: 2022 | C9: Abril | D9: 9225 | E9: 2155 | F9: 7070 | H9: 2023 | I9: Abril | J9: 9700 | K9: 6045 | L9: 3655
B10: 2022 | C10: Mayo | D10: 2400 | E10: 2451 | F10: -51 | H10: 2023 | I10: Mayo | J10: 1830 | K10: 2730 | L10: -900
B11: 2022 | C11: Junio | D11: 1845 | E11: 2065 | F11: -220 | H11: 2023 | I11: Junio | J11: 1840 | K11: 2770 | L11: -930
B12: 2022 | C12: Julio | D12: 4025 | E12: 3040 | F12: 985 | H12: 2023 | I12: Julio | J12: 4095 | K12: 3575 | L12: 520
B13: 2022 | C13: Agosto | D13: 2525 | E13: 4016 | F13: -1491 | H13: 2023 | I13: Agosto | J13: 2915 | K13: 3120 | L13: -205
B14: 2022 | C14: Septiembre | D14: 1880 | E14: 4700 | F14: -2820 | H14: 2023 | I14: Septiembre | J14: 1955 | K14: 2060 | L14: -105
B15: 2022 | C15: Octubre | D15: 3980 | E15: 3545 | F15: 435 | H15: 2023 | I15: Octubre | J15: 4235 | K15: 4420 | L15: -185
B16: 2022 | C16: Noviembre | D16: 1800 | E16: 2165 | F16: -365 | H16: 2023 | I16: Noviembre | J16: 1975 | K16: 2690 | L16: -715
B17: 2022 | C17: Diciembre | D17: 1790 | E17: 2140 | F17: -350 | H17: 2023 | I17: Diciembre | J17: 1975 | K17: 3275 | L17: -1300
B18: Total: | D18: 37330 | E18: 38672 | F18: -1342 | H18: Total: | J18: 37980 | K18: 46435 | L18: -8455
B22: Categoría | C22: Importe | D22: Total | F22: 2023
B23: Automovil:Combustible | C23: -175 | H23: Enero | I23: Febrero | J23: Marzo | K23: Abril | L23: Mayo | M23: Junio | N23: Julio | O23: Agosto | P23: Septiembre | Q23: Octubre | R23: Noviembre | S23: Diciembre
B24: Automovil:Compra/Renting | C24: -400 | F24: Ahorro-Inversion | H24: 0 | I24: 0 | J24: 0 | K24: -2300 | L24: -240 | M24: -225 | N24: -250 | O24: -150 | P24: -160 | Q24: -795 | R24: -95 | S24: -130 | T24: -4345 | U24: =AVERAGE(H24:S24) -> -362.08333
B25: Automovil:Impuestos | C25: -70 | F25: Automovil:Mantenimiento | H25: -10 | I25: 0 | J25: 0 | K25: 0 | L25: 0 | M25: 0 | N25: 0 | O25: 0 | P25: 0 | Q25: 0 | R25: -10 | S25: 0 | T25: -20 | U25: =AVERAGE(H25:S25) -> -1.6666667
B26: Automovil:Mantenimiento | C26: -30 | F26: Automovil:Combustible | H26: 0 | I26: -20 | J26: -20 | K26: 0 | L26: -20 | M26: -20 | N26: -30 | O26: -20 | P26: -20 | Q26: -40 | R26: 0 | S26: -30 | T26: -220 | U26: =AVERAGE(H26:S26) -> -18.333333
B27: Automovil:Parking-Peajes | C27: -45 | F27: Automovil:Parking-Peajes | H27: 0 | I27: -5 | J27: 0 | K27: 0 | L27: -5 | M27: 0 | N27: 0 | O27: 0 | P27: 0 | Q27: 0 | R27: 0 | S27: -25 | T27: -35 | U27: =AVERAGE(H27:S27) -> -2.9166667
B28: Total categoría: | D28: -720 | F28: Automovil:Impuestos | H28: -100 | I28: 0 | J28: 0 | K28: 0 | L28: -70 | M28: 0 | N28: -120 | O28: 0 | P28: 0 | Q28: 0 | R28: 0 | S28: 0 | T28: -290 | U28: =AVERAGE(H28:S28) -> -24.166667
B29: Comida:Dietas | C29: -3840 | D29: -3840 | F29: Automovil:Compra/Renting | H29: 0 | I29: -8500 | J29: -280 | K29: -1300 | L29: -280 | M29: 0 | N29: 0 | O29: 0 | P29: 0 | Q29: -1000 | R29: 0 | S29: 0 | T29: -11360 | U29: =AVERAGE(H29:S29) -> -946.66667
B30: Deporte:Gimnasio | C30: -260 | F30: Comida:Dietas | H30: -285 | I30: -275 | J30: -300 | K30: -405 | L30: -370 | M30: -480 | N30: -375 | O30: -275 | P30: -445 | Q30: -415 | R30: -475 | S30: -450 | T30: -4550 | U30: =AVERAGE(H30:S30) -> -379.16667
B31: Deporte:Ropa | C31: -25 | F31: Deporte:Ropa | H31: 0 | I31: 0 | J31: 0 | K31: 0 | L31: -25 | M31: 0 | N31: 0 | O31: 0 | P31: -45 | Q31: -50 | R31: 0 | S31: 0 | T31: -120 | U31: =AVERAGE(H31:S31) -> -10
B32: Total categoría: | D32: -285 | F32: Deporte:Gimnasio | H32: -65 | I32: 0 | J32: 0 | K32: -65 | L32: 0 | M32: 0 | N32: -65 | O32: 0 | P32: 0 | Q32: -105 | R32: -15 | S32: -15 | T32: -330 | U32: =AVERAGE(H32:S32) -> -27.5
B33: Formacion-Cultura:Papeleria | C33: -5 | D33: -5 | F33: Formacion-Cultura:Papeleria | H33: 0 | I33: 0 | J33: 0 | K33: 0 | L33: 0 | M33: 0 | N33: 0 | O33: 0 | P33: 0 | Q33: 0 | R33: -5 | S33: 0 | T33: -5 | U33: =AVERAGE(H33:S33) -> -0.41666667
B34: GastoFijoMensual:Agua | C34: -340 | F34: GastoFijoMensual:Telefono | H34: -35 | I34: -35 | J34: -35 | K34: -40 | L34: -40 | M34: -40 | N34: -40 | O34: -40 | P34: -40 | Q34: -40 | R34: -40 | S34: -40 | T34: -465 | U34: =AVERAGE(H34:S34) -> -38.75
B35: GastoFijoMensual:Alquiler | C35: -9940 | F35: GastoFijoMensual:Electricidad | H35: 0 | I35: -125 | J35: 0 | K35: -110 | L35: 0 | M35: -100 | N35: 0 | O35: -100 | P35: 0 | Q35: -85 | R35: 0 | S35: -50 | T35: -570 | U35: =AVERAGE(H35:S35) -> -47.5
B36: GastoFijoMensual:Electricidad | C36: -665 | F36: GastoFijoMensual:Gas | H36: 0 | I36: -45 | J36: 0 | K36: -60 | L36: 0 | M36: -25 | N36: 0 | O36: -20 | P36: 0 | Q36: -25 | R36: 0 | S36: -20 | T36: -195 | U36: =AVERAGE(H36:S36) -> -16.25
B37: GastoFijoMensual:Gas | C37: -190 | F37: GastoFijoMensual:Alquiler | H37: -870 | I37: -870 | J37: -870 | K37: -870 | L37: -870 | M37: -870 | N37: -870 | O37: -870 | P37: -870 | Q37: -870 | R37: -870 | S37: -870 | T37: -10440 | U37: =AVERAGE(H37:S37) -> -870
B38: GastoFijoMensual:Telefono | C38: -420 | F38: GastoFijoMensual:Agua | H38: 0 | I38: -55 | J38: 0 | K38: -55 | L38: 0 | M38: -55 | N38: 0 | O38: -55 | P38: 0 | Q38: -55 | R38: 0 | S38: -55 | T38: -330 | U38: =AVERAGE(H38:S38) -> -27.5
B39: Total categoría: | D39: -11555 | F39: Hogar y Vestuario:Ropa | H39: 0 | I39: 0 | J39: 0 | K39: 0 | L39: 0 | M39: 0 | N39: 0 | O39: 0 | P39: -5 | Q39: 0 | R39: 0 | S39: 0 | T39: -5 | U39: =AVERAGE(H39:S39) -> -0.41666667
B40: Hogar y Vestuario:Mobiliario | C40: -185 | F40: Hogar y Vestuario:Niños | H40: -50 | I40: -45 | J40: -110 | K40: -275 | L40: -535 | M40: -600 | N40: -115 | O40: -30 | P40: -40 | Q40: -90 | R40: -50 | S40: -50 | T40: -1990 | U40: =AVERAGE(H40:S40) -> -165.83333
B41: Hogar y Vestuario:Niños | C41: -2845 | F41: Impuestos:Hacienda | H41: 0 | I41: 0 | J41: 0 | K41: -35 | L41: 0 | M41: 0 | N41: 0 | O41: 0 | P41: 0 | Q41: 0 | R41: 0 | S41: 0 | T41: -35 | U41: =AVERAGE(H41:S41) -> -2.9166667
B42: Hogar y Vestuario:Ropa | C42: -160 | F42: Ingresos:Salario | H42: 3900 | I42: 1790 | J42: 1770 | K42: 9700 | L42: 1830 | M42: 1840 | N42: 4095 | O42: 2915 | P42: 1955 | Q42: 4235 | R42: 1975 | S42: 1975 | T42: 37980 | U42: =AVERAGE(H42:S42) -> 3165
B43: Hogar y Vestuario:Varios | C43: -40 | F43: Loteria | H43: -25 | I43: -55 | J43: -35 | K43: -95 | L43: -75 | M43: -60 | N43: -30 | O43: -50 | P43: -30 | Q43: -45 | R43: -85 | S43: -85 | T43: -670 | U43: =AVERAGE(H43:S43) -> -55.833333
B44: Total categoría: | D44: -3230 | F44: Ocio | H44: -35 | I44: 0 | J44: 0 | K44: 0 | L44: 0 | M44: 0 | N44: 0 | O44: -75 | P44: 0 | Q44: 0 | R44: 0 | S44: 0 | T44: -110 | U44: =AVERAGE(H44:S44) -> -9.1666667
B45: Impuestos:Hacienda | C45: 575 | D45: 575 | F45: Ocio:Revistas-Colecciones | H45: -50 | I45: 0 | J45: 0 | K45: -50 | L45: 0 | M45: 0 | N45: 0 | O45: 0 | P45: 0 | Q45: 0 | R45: 0 | S45: 0 | T45: -100 | U45: =AVERAGE(H45:S45) -> -8.3333333
B46: Ingresos:Salario | C46: 36755 | D46: 36755 | F46: Ocio:FinSemana y Festivos | H46: -180 | I46: -55 | J46: -75 | K46: -135 | L46: -80 | M46: -115 | N46: -75 | O46: -125 | P46: -180 | Q46: -190 | R46: -65 | S46: -200 | T46: -1475 | U46: =AVERAGE(H46:S46) -> -122.91667
B47: Loteria | C47: -800 | D47: -800 | F47: Ocio:Otros | H47: 0 | I47: 0 | J47: -10 | K47: 0 | L47: 0 | M47: 0 | N47: -10 | O47: 0 | P47: -160 | Q47: -75 | R47: 0 | S47: 0 | T47: -255 | U47: =AVERAGE(H47:S47) -> -21.25
...

Sheet Principal
C3: 2003 | D3: 2004 | E3: 2005 | F3: 2006 | G3: 2007 | H3: 2008 | I3: 2009 | J3: 2010 | K3: 2011 | L3: 2012 | M3: 2013 | N3: 2014 | O3: 2015 | P3: 2016 | Q3: 2017 | R3: 2018 | S3: 2019 | T3: 2020 | U3: 2021 | V3: 2022 | W3: 2023 | X3: 2024 | Y3: 2025 | Z3: 2026 | AA3: 2027 | AB3: TOTALES | AC3: Promedios
B5: Salario | C5: 17490 | D5: 22055 | E5: 15700 | F5: 20050 | G5: 24000 | H5: 24600 | I5: 36125 | J5: 40330 | K5: 16970 | L5: 20615 | M5: 23960 | N5: 26425 | O5: 29035 | P5: 23000 | Q5: 31130 | R5: 31500 | S5: 31575 | T5: 32245 | U5: 35815 | V5: 36755 | W5: 37980 | X5: 44150 | Y5: 46200 | AB5: =SUM(C5:Y5) -> 667705 | AC5: =AVERAGE(C5:X5) -> 28250.227 | AD5: Salario
B6: Salario (Pagas extraordinarias) | C6: 4750 | D6: 7600 | E6: 11175 | F6: 1800 | G6: 2575 | H6: 2100 | I6: 20825 | J6: 0 | K6: 2750 | L6: 3510 | M6: 1825 | N6: 0 | O6: 0 | P6: 8000 | Q6: 0 | R6: 250 | S6: 0 | T6: 0 | U6: 0 | V6: 0 | W6: 0 | X6: 0 | Y6: 0 | AB6: =SUM(C6:Y6) -> 67160 | AC6: =AVERAGE(C6:X6) -> 3052.7273 | AD6: Salario (Pagas extraordinarias)
B7: Otros ingresos | C7: 2500 | D7: 0 | E7: 0 | F7: 13000 | G7: 0 | H7: 0 | I7: 0 | J7: 750 | K7: 0 | L7: 720 | M7: 90 | N7: 1440 | O7: 0 | P7: 625 | Q7: 135 | R7: 0 | S7: 0 | T7: 0 | U7: 0 | V7: 575 | W7: 0 | X7: 0 | Y7: 0 | AB7: =SUM(C7:Y7) -> 19835 | AC7: =AVERAGE(C7:X7) -> 901.59091 | AD7: Otros ingresos
B8: Reajuste del saldo | C8: 0 | D8: 0 | E8: 0 | F8: 0 | G8: 0 | H8: 0 | I8: 0 | J8: 0 | K8: 0 | L8: 0 | M8: 0 | N8: 0 | O8: 0 | P8: 0 | Q8: 0 | R8: 0 | S8: 0 | T8: 0 | U8: 0 | V8: 0 | W8: 0 | X8: 0 | Y8: 0 | AB8: =SUM(C8:Y8) -> 0 | AC8: =AVERAGE(C8:X8) -> 0 | AD8: Reajuste del saldo
B9: Inversión | C9: 0 | D9: 0 | E9: 12000 | F9: 0 | G9: 0 | H9: 0 | I9: 0 | J9: 0 | K9: 0 | L9: 0 | M9: 0 | N9: 0 | O9: 0 | P9: 0 | Q9: 0 | R9: 0 | S9: 0 | T9: 0 | U9: 0 | V9: 0 | W9: 0 | X9: 0 | Y9: 0 | AB9: =SUM(C9:Y9) -> 12000 | AC9: =AVERAGE(C9:X9) -> 545.45455 | AD9: Inversión
B10: Ayudas familiares | C10: 0 | D10: 0 | E10: 0 | F10: 0 | G10: 0 | H10: 0 | I10: 0 | J10: 0 | K10: 0 | L10: 0 | M10: 0 | N10: 0 | O10: 0 | P10: 0 | Q10: 0 | R10: 0 | S10: 0 | T10: 0 | U10: 0 | V10: 0 | W10: 0 | X10: 0 | Y10: 0 | AB10: =SUM(C10:Y10) -> 0 | AC10: =AVERAGE(C10:X10) -> 0 | AD10: Ayudas familiares
B11: Bolsa de Ahorro | C11: 355 | D11: 0 | E11: 0 | F11: 0 | G11: 0 | H11: 0 | I11: 0 | J11: 0 | K11: 0 | L11: 0 | M11: 0 | N11: 0 | O11: 0 | P11: 0 | Q11: 0 | R11: 0 | S11: 0 | T11: 0 | U11: 0 | V11: 0 | W11: 0 | X11: 0 | Y11: 0 | AB11: =SUM(C11:Y11) -> 355 | AC11: =AVERAGE(C11:X11) -> 16.136364 | AD11: Bolsa de Ahorro
B12: Varios | C12: 500 | D12: 0 | E12: 0 | F12: 0 | G12: 0 | H12: 0 | I12: 0 | J12: 0 | K12: 0 | L12: 0 | M12: 0 | N12: 0 | O12: 0 | P12: 0 | Q12: 0 | R12: 0 | S12: 0 | T12: 0 | U12: 0 | V12: 0 | W12: 0 | X12: 0 | Y12: 0 | AB12: =SUM(C12:Y12) -> 500 | AC12: =AVERAGE(C12:X12) -> 22.727273 | AD12: Varios
B13: TOTAL INGRESOS | C13: =SUM(C5:C12) -> 25595 | D13: =SUM(D5:D12) -> 29655 | E13: =SUM(E5:E12) -> 38875 | F13: =SUM(F5:F12) -> 34850 | G13: =SUM(G5:G12) -> 26575 | H13: =SUM(H5:H12) -> 26700 | I13: =SUM(I5:I12) -> 56950 | J13: =SUM(J5:J12) -> 41080 | ... Y13: =SUM(Y5:Y12) -> 46200 | AB13: =SUM(C13:Y13) -> 767555 | AC13: =AVERAGE(C13:X13) -> 32788.864 | AD13: Ingresos 2003-2025
B15: Coche | C15: 5605 | D15: 5460 | E15: 5460 | F15: 5460 | G15: 5460 | H15: 7380 | I15: 18650 | J15: 0 | K15: 0 | L15: 0 | M15: 9300 | N15: 0 | O15: 0 | P15: 10600 | Q15: 0 | R15: 0 | S15: 3450 | T15: 2175 | U15: 2500 | V15: 400 | W15: 11650 | X15: 2735 | Y15: 4160 | AB15: =SUM(C15:Y15) -> 100445 | AC15: =AVERAGE(C15:Y15) -> 4367.1739
B16: Gimnasios | C16: 325 | D16: 445 | E16: 320 | F16: 395 | G16: 400 | H16: 615 | I16: 610 | J16: 545 | K16: 620 | L16: 655 | M16: 595 | N16: 865 | O16: 330 | P16: 375 | Q16: 320 | R16: 295 | S16: 320 | T16: 300 | U16: 115 | V16: 260 | W16: 330 | X16: 610 | Y16: 580 | AB16: =SUM(C16:Y16) -> 10225 | AC16: =AVERAGE(C16:Y16) -> 444.56522
B17: Plan de Ahorro / Inversion | C17: 720 | D17: 760 | E17: 1200 | F17: 850 | G17: 350 | H17: 0 | I17: 0 | J17: 0 | K17: 0 | L17: 0 | M17: 0 | N17: 0 | O17: 600 | P17: 650 | Q17: 400 | R17: 335 | S17: 320 | T17: 1110 | U17: 120 | V17: 0 | W17: 0 | X17: 3048 | Y17: 7290 | AB17: =SUM(C17:Y17) -> 17753 | AC17: =AVERAGE(C17:Y17) -> 771.86957
B18: Traspaso Caixa Catalunya / BBVA | C18: 1500 | D18: 100 | E18: 1200 | F18: 0 | G18: 60 | H18: 0 | I18: 0 | J18: 460 | K18: 470 | L18: 170 | M18: 180 | N18: 160 | O18: 160 | P18: 50 | Q18: 710 | R18: 2000 | S18: 0 | T18: 0 | U18: 0 | V18: 7300 | W18: 6945 | X18: 2950 | Y18: 1300 | AB18: =SUM(C18:Y18) -> 25715 | AC18: =AVERAGE(C18:Y18) -> 1118.0435
B19: Comida y bebida | C19: 605 | D19: 615 | E19: 1810 | F19: 2370 | G19: 2155 | H19: 2255 | I19: 2390 | J19: 3360 | K19: 2700 | L19: 1665 | M19: 1080 | N19: 1305 | O19: 1425 | P19: 1815 | Q19: 2470 | R19: 1770 | S19: 2150 | T19: 2925 | U19: 3655 | V19: 3840 | W19: 4550 | X19: 5475 | Y19: 6395 | AB19: =SUM(C19:Y19) -> 58780 | AC19: =AVERAGE(C19:Y19) -> 2555.6522
B20: Primitiva y otras loterias | C20: 149 | D20: 264 | E20: 335 | F20: 415 | G20: 345 | H20: 415 | I20: 400 | J20: 425 | K20: 425 | L20: 560 | M20: 470 | N20: 770 | O20: 415 | P20: 550 | Q20: 825 | R20: 1025 | S20: 725 | T20: 580 | U20: 600 | V20: 800 | W20: 670 | X20: 730 | Y20: 805 | AB20: =SUM(C20:Y20) -> 12698 | AC20: =AVERAGE(C20:Y20) -> 552.08696
B21: Tfno, Agua, Gas, Luz, etc | C21: 160 | D21: 705 | E21: 835 | F21: 870 | G21: 1215 | H21: 935 | I21: 1360 | J21: 2150 | K21: 2130 | L21: 1740 | M21: 1510 | N21: 2115 | O21: 1955 | P21: 1775 | Q21: 1665 | R21: 1755 | S21: 1725 | T21: 1770 | U21: 1765 | V21: 1615 | W21: 1560 | X21: 1715 | Y21: 2885 | AB21: =SUM(C21:Y21) -> 35910 | AC21: =AVERAGE(C21:Y21) -> 1561.3043
B22: Otros | C22: 780 | D22: 1725 | E22: 2110 | F22: 2685 | G22: 2550 | H22: 1390 | I22: 1625 | J22: 1890 | K22: 1410 | L22: 180 | M22: 180 | N22: 480 | O22: 235 | P22: 700 | Q22: 1015 | R22: 1135 | S22: 900 | T22: 180 | U22: 210 | V22: 625 | W22: 255 | X22: 350 | Y22: 120 | AB22: =SUM(C22:Y22) -> 22730 | AC22: =AVERAGE(C22:Y22) -> 988.26087
B23: Seguros (coche, vida, tarjetas) | C23: 900 | D23: 900 | E23: 850 | F23: 725 | G23: 0 | H23: 0 | I23: 365 | J23: 690 | K23: 755 | L23: 755 | M23: 805 | N23: 800 | O23: 775 | P23: 850 | Q23: 870 | R23: 890 | S23: 395 | T23: 385 | U23: 355 | V23: 385 | W23: 430 | X23: 880 | Y23: 930 | AB23: =SUM(C23:Y23) -> 14690 | AC23: =AVERAGE(C23:Y23) -> 638.69565
B24: Asociaciones, subscripciones,… | C24: 270 | D24: 0 | E24: 0 | F24: 0 | G24: 30 | H24: 30 | I24: 30 | J24: 100 | K24: 305 | L24: 140 | M24: 50 | N24: 50 | O24: 50 | P24: 50 | Q24: 120 | R24: 150 | S24: 215 | T24: 180 | U24: 220 | V24: 100 | W24: 100 | X24: 100 | Y24: 620 | AB24: =SUM(C24:Y24) -> 2910 | AC24: =AVERAGE(C24:Y24) -> 126.52174 | AD24: Netflix, Google, MS
B26: Alquiler | C26: 0 | D26: 0 | E26: 0 | F26: 0 | G26: 0 | H26: 8210 | I26: 7315 | J26: 8470 | K26: 8570 | L26: 10910 | M26: 8640 | N26: 9585 | O26: 8880 | P26: 8880 | Q26: 9120 | R26: 9550 | S26: 9840 | T26: 9675 | U26: 9840 | V26: 9940 | W26: 10440 | X26: 10740 | Y26: 11035 | AB26: =SUM(C26:Y26) -> 169640 | AC26: =AVERAGE(C26:Y26) -> 7375.6522
B27: Salud y cuidado personal | C27: 30 | D27: 40 | E27: 120 | F27: 50 | G27: 60 | H27: 360 | I27: 380 | J27: 45 | K27: 140 | L27: 225 | M27: 625 | N27: 135 | O27: 480 | P27: 100 | Q27: 135 | R27: 165 | S27: 125 | T27: 750 | U27: 170 | V27: 150 | W27: 215 | X27: 5785 | Y27: 1155 | AB27: =SUM(C27:Y27) -> 11440 | AC27: =AVERAGE(C27:Y27) -> 497.3913
B28: Averías (fontanería, etc.) | C28: 0 | D28: 0 | E28: 0 | F28: 0 | G28: 0 | H28: 0 | I28: 0 | J28: 0 | K28: 0 | L28: 0 | M28: 160 | N28: 0 | O28: 0 | P28: 0 | Q28: 0 | R28: 0 | S28: 0 | T28: 0 | U28: 0 | V28: 0 | W28: 0 | X28: 15 | Y28: 0 | AB28: =SUM(C28:Y28) -> 175 | AC28: =AVERAGE(C28:Y28) -> 7.6086957
B29: Material oficina (cuadernos, salidas, etc.) | C29: 65 | D29: 40 | E29: 25 | F29: 90 | G29: 45 | H29: 0 | I29: 55 | J29: 10 | K29: 5 | L29: 0 | M29: 90 | N29: 15 | O29: 35 | P29: 75 | Q29: 15 | R29: 15 | S29: 105 | T29: 60 | U29: 20 | V29: 5 | W29: 5 | X29: 10 | Y29: 5 | AB29: =SUM(C29:Y29) -> 790 | AC29: =AVERAGE(C29:Y29) -> 34.347826
B30: Gastos trabajo | C30: 2885 | D30: 4205 | E30: 830 | F30: 830 | G30: 550 | H30: 2860 | I30: 2170 | J30: 1125 | K30: 0 | L30: 0 | M30: 100 | N30: 350 | O30: 290 | P30: 325 | Q30: 65 | R30: 0 | S30: 70 | T30: 0 | U30: 10 | V30: 0 | W30: 0 | X30: 0 | Y30: 0 | AB30: =SUM(C30:Y30) -> 16665 | AC30: =AVERAGE(C30:Y30) -> 724.56522 | AD30: (no contabilizables)
B31: Regalos (cumpleaños, reyes, …) | C31: 550 | D31: 1365 | E31: 1730 | F31: 720 | G31: 1305 | H31: 1145 | I31: 1000 | J31: 2505 | K31: 1450 | L31: 940 | M31: 845 | N31: 745 | O31: 1170 | P31: 1025 | Q31: 1080 | R31: 550 | S31: 1000 | T31: 1280 | U31: 445 | V31: 695 | W31: 1220 | X31: 315 | Y31: 1800 | AB31: =SUM(C31:Y31) -> 24880 | AC31: =AVERAGE(C31:Y31) -> 1081.7391
B32: Ocio (salidas, cenas, revistas,...) | C32: 795 | D32: 1665 | E32: 1650 | F32: 1520 | G32: 1695 | H32: 1745 | I32: 1745 | J32: 1090 | K32: 1315 | L32: 1655 | M32: 1150 | N32: 930 | O32: 990 | P32: 1150 | Q32: 1455 | R32: 1355 | S32: 1700 | T32: 580 | U32: 910 | V32: 1545 | W32: 1730 | X32: 1770 | Y32: 1880 | AB32: =SUM(C32:Y32) -> 32020 | AC32: =AVERAGE(C32:Y32) -> 1392.1739
B33: Ropa y calzado | C33: 220 | D33: 470 | E33: 185 | F33: 125 | G33: 305 | H33: 90 | I33: 200 | J33: 0 | K33: 580 | L33: 235 | M33: 215 | N33: 10 | O33: 125 | P33: 1000 | Q33: 170 | R33: 230 | S33: 75 | T33: 65 | U33: 65 | V33: 160 | W33: 5 | X33: 305 | Y33: 45 | AB33: =SUM(C33:Y33) -> 4880 | AC33: =AVERAGE(C33:Y33) -> 212.17391
B34: Vacaciones | C34: 950 | D34: 475 | E34: 1200 | F34: 800 | G34: 1625 | H34: 150 | I34: 1030 | J34: 0 | K34: 1105 | L34: 1265 | M34: 730 | N34: 65 | O34: 1130 | P34: 2475 | Q34: 2025 | R34: 4425 | S34: 1800 | T34: 2175 | U34: 2785 | V34: 3215 | W34: 3565 | X34: 4610 | Y34: 2300 | AB34: =SUM(C34:Y34) -> 39900 | AC34: =AVERAGE(C34:Y34) -> 1734.7826
B35: Reparaciones del automóvil | C35: 300 | D35: 630 | E35: 0 | F35: 340 | G35: 10 | H35: 0 | I35: 0 | J35: 0 | K35: 0 | L35: 340 | M35: 85 | N35: 440 | O35: 255 | P35: 15 | Q35: 165 | R35: 520 | S35: 155 | T35: 0 | U35: 165 | V35: 100 | W35: 20 | X35: 15 | Y35: 0 | AB35: =SUM(C35:Y35) -> 3555 | AC35: =AVERAGE(C35:Y35) -> 154.56522
B36: Libros | C36: 205 | D36: 175 | E36: 310 | F36: 60 | G36: 190 | H36: 55 | I36: 270 | J36: 190 | K36: 115 | L36: 60 | M36: 25 | N36: 365 | O36: 35 | P36: 100 | Q36: 265 | R36: 120 | S36: 60 | T36: 40 | U36: 0 | V36: 0 | W36: 5 | X36: 0 | Y36: 0 | AB36: =SUM(C36:Y36) -> 2645 | AC36: =AVERAGE(C36:Y36) -> 115
B37: Automóvil (combustible + párking) | C37: 505 | D37: 430 | E37: 570 | F37: 425 | G37: 320 | H37: 30 | I37: 850 | J37: 515 | K37: 630 | L37: 1565 | M37: 1765 | N37: 1325 | O37: 1110 | P37: 1150 | Q37: 1070 | R37: 1200 | S37: 1050 | T37: 390 | U37: 60 | V37: 220 | W37: 35 | X37: 370 | Y37: 200 | AB37: =SUM(C37:Y37) -> 15785 | AC37: =AVERAGE(C37:Y37) -> 686.30435
B38: Otros medios de transporte (tren, metro,...) | C38: 46 | D38: 90 | E38: 300 | F38: 435 | G38: 350 | H38: 450 | I38: 750 | J38: 340 | K38: 590 | L38: 180 | M38: 55 | N38: 145 | O38: 30 | P38: 30 | Q38: 45 | R38: 15 | S38: 20 | T38: 40 | U38: 0 | V38: 65 | W38: 25 | X38: 270 | Y38: 30 | AB38: =SUM(C38:Y38) -> 4301 | AC38: =AVERAGE(C38:Y38) -> 187
B39: Material Deportivo | C39: 115 | D39: 50 | E39: 30 | F39: 0 | G39: 280 | H39: 50 | I39: 150 | J39: 410 | K39: 60 | L39: 110 | M39: 10 | N39: 0 | O39: 0 | P39: 50 | Q39: 30 | R39: 10 | S39: 50 | T39: 35 | U39: 90 | V39: 25 | W39: 120 | X39: 75 | Y39: 100 | AB39: =SUM(C39:Y39) -> 1850 | AC39: =AVERAGE(C39:Y39) -> 80.434783
B40: Viajes Personales, Excursiones | C40: 375 | D40: 805 | E40: 1710 | F40: 1510 | G40: 2130 | H40: 655 | I40: 1550 | J40: 630 | K40: 225 | L40: 400 | M40: 405 | N40: 0 | O40: 20 | P40: 0 | Q40: 80 | R40: 0 | S40: 0 | T40: 0 | U40: 0 | V40: 0 | W40: 0 | X40: 0 | Y40: 1550 | AB40: =SUM(C40:AA40) -> 12045 | AC40: =AVERAGE(C40:Y40) -> 523.69565
B41: Videos, revistas, periodicos y colecciones | C41: 176 | D41: 395 | E41: 360 | F41: 430 | G41: 295 | H41: 105 | I41: 225 | J41: 305 | K41: 170 | L41: 215 | M41: 225 | N41: 520 | O41: 275 | P41: 510 | Q41: 360 | R41: 315 | S41: 235 | T41: 180 | U41: 150 | V41: 300 | W41: 100 | X41: 0 | Y41: 25 | AB41: =SUM(C41:Y41) -> 5871 | AC41: =AVERAGE(C41:Y41) -> 255.26087
B42: Formación | C42: 2150 | D42: 780 | E42: 800 | F42: 610 | G42: 0 | H42: 0 | I42: 2100 | J42: 0 | K42: 995 | L42: 0 | M42: 0 | N42: 275 | O42: 250 | P42: 0 | Q42: 390 | R42: 140 | S42: 50 | T42: 0 | U42: 110 | V42: 0 | W42: 5 | X42: 0 | Y42: 0 | AB42: =SUM(C42:AA42) -> 8655 | AC42: =AVERAGE(C42:Y42) -> 376.30435
B43: Tecnologia, Electronica, Informatica | C43: 275 | D43: 275 | E43: 1785 | F43: 1960 | G43: 1770 | H43: 2105 | I43: 1000 | J43: 2625 | K43: 135 | L43: 475 | M43: 300 | N43: 5 | O43: 2285 | P43: 300 | Q43: 1795 | R43: 3840 | S43: 750 | T43: 1660 | U43: 1770 | V43: 3855 | W43: 10 | X43: 2865 | Y43: 205 | AB43: =SUM(C43:AA43) -> 32045 | AC43: =AVERAGE(C43:Y43) -> 1393.2609
B44: Utensilios | C44: 700 | D44: 275 | E44: 0 | F44: 0 | G44: 60 | H44: 0 | I44: 0 | J44: 50 | K44: 0 | L44: 0 | M44: 0 | N44: 100 | O44: 0 | P44: 0 | Q44: 0 | R44: 50 | S44: 0 | T44: 0 | U44: 0 | V44: 40 | W44: 5 | X44: 10 | Y44: 50 | AB44: =SUM(C44:AA44) -> 1340 | AC44: =AVERAGE(C44:Y44) -> 58.26087
B45: Hacienda y otros impuestos | C45: 575 | D45: 300 | E45: 1900 | F45: 500 | G45: 0 | H45: 0 | I45: 0 | J45: 8795 | K45: 1610 | L45: 25 | M45: 70 | N45: 4495 | O45: 70 | P45: 0 | Q45: 0 | R45: 70 | S45: 70 | T45: 105 | U45: 210 | V45: 0 | W45: 0 | X45: 70 | Y45: 155 | AB45: =SUM(C45:AA45) -> 19020 | AC45: =AVERAGE(C45:Y45) -> 826.95652
...

Sheet Graficos
C5: 1991 | D5: 1992 | E5: 1993 | F5: 1994 | G5: 1995 | H5: 1996 | I5: 1997 | J5: 1998 | K5: 1999 | L5: 2000 | M5: 2001 | N5: 2002 | O5: 2003 | P5: 2004 | Q5: 2005 | R5: 2006 | S5: 2007 | T5: 2008 | U5: 2009 | V5: 2010 | W5: 2011 | X5: 2012 | Y5: 2013 | Z5: 2014 | AA5: 2015
B6: Ingresos | C6: 5190.94 | D6: 4297.24 | E6: 5736.06 | F6: 9315.69 | G6: 9934.73 | H6: 12278.68 | I6: 12278.68 | J6: 11629.58 | K6: 14123.78 | L6: 13522.77 | M6: 16236 | N6: 20900 | O6: 25595 | P6: 29655 | Q6: 38875 | R6: 34850 | S6: 26575 | T6: 26700 | U6: 56950 | V6: 41080 | W6: 19720 | X6: 24845 | Y6: 25875 | Z6: 27865 | AA6: 29035 | AB6: Ingresos
B7: Gastos | C7: 5339.99 | D7: 4318.27 | E7: 4946.33 | F7: 9177.45 | G7: 10920.39 | H7: 11467.31 | I7: 12218.58 | J7: 11719.74 | K7: 14328.13 | L7: 14003.58 | M7: 14997 | N7: 19500 | O7: 21996 | P7: 19294 | Q7: 27015 | R7: 23585 | S7: 23200 | T7: 29780 | U7: 44265 | V7: 39830 | W7: 26570 | X7: 28635 | Y7: 30135 | Z7: 33140 | AA7: 24200 | AB7: Gastos
C8: =C6-C7 -> -149.05 | D8: =D6-D7 -> -21.03 | E8: =E6-E7 -> 789.73 | F8: =F6-F7 -> 138.24 | G8: =G6-G7 -> -985.66 | H8: =H6-H7 -> 811.37 | I8: =I6-I7 -> 60.1 | J8: =J6-J7 -> -90.16 | ... AA8: =AA6-AA7 -> 4835
M10: 2016 | N10: 2017 | O10: 2018 | P10: 2019 | Q10: 2020 | R10: 2021 | S10: 2022 | T10: 2023 | U10: 2024 | V10: 2025 | W10: 2026 | X10: 2027 | Y10: 2028 | Z10: 2029 | AA10: 2030
D11: Total INGRESOS | E11: =SUM(C6:AA6)+SUM(M11:AA11) -> 902969.15 | G11: Saldo TOTAL | H11: =E11-E12 -> 30207.38 | M11: 31595 | N11: 31265 | O11: 31750 | P11: 31575 | Q11: 32245 | R11: 35815 | S11: 37330 | T11: 37980 | U11: 44150 | V11: 46200 | AB11: Ingresos
D12: Total GASTOS | E12: =SUM(C7:AA7)+SUM(M12:AA12) -> 872761.77 | M12: 36075 | N12: 27740 | O12: 34135 | P12: 29100 | Q12: 27695 | R12: 31025 | S12: 38670 | T12: 46435 | U12: 48705 | V12: 48600 | AB12: Gastos
M13: =M11-M12 -> -4480 | N13: =N11-N12 -> 3525 | O13: =O11-O12 -> -2385 | P13: =P11-P12 -> 2475 | Q13: =Q11-Q12 -> 4550 | R13: =R11-R12 -> 4790 | S13: =S11-S12 -> -1340 | T13: =T11-T12 -> -8455 | ... V13: =V11-V12 -> -2400
C43: Ingresos | D43: Gastos
A44: 1991 | B44: Ene 91 | C44: 325 | D44: 335 | E44: =C44-D44 -> -10
B45: Febrero | C45: 0 | D45: 405 | E45: =C45-D45 -> -405 | H45: 2020
B46: Marzo | C46: 1085 | D46: 450 | E46: =C46-D46 -> 635 | H46: Concepto | I46: Ene | J46: Mar | K46: May | L46: Jul | M46: Oct | N46: Dic
B47: Abril | C47: 545 | D47: 220 | E47: =C47-D47 -> 325 | H47: CC | I47: 27000 | J47: 26500 | K47: 28500 | L47: 28500 | M47: 31500 | N47: 32500 | O47: =N47/$N$51 -> 0.56788398
B48: Mayo | C48: 545 | D48: 430 | E48: =C48-D48 -> 115 | H48: SIAL | I48: 8900 | J48: 8950 | K48: 9000 | L48: 9050 | M48: 9150 | N48: 9230 | O48: =N48/$N$51 -> 0.16127905
B49: Junio | C49: 545 | D49: 425 | E49: =C49-D49 -> 120 | H49: PP | I49: 13750 | J49: 13700 | K49: 13500 | L49: 13950 | M49: 14675 | N49: 15500 | O49: =N49/$N$51 -> 0.27083697
B50: Julio | C50: 545 | D50: 360 | E50: =C50-D50 -> 185
B51: Agosto | C51: 545 | D51: 735 | E51: =C51-D51 -> -190 | H51: TOTAL | I51: 49650 | J51: 49150 | K51: 51000 | L51: 51500 | M51: 55325 | N51: 57230
B52: Septiembre | C52: 545 | D52: 665 | E52: =C52-D52 -> -120 | H52: 2021
B53: Octubre | C53: 545 | D53: 1355 | E53: =C53-D53 -> -810 | H53: Concepto | I53: Ene | J53: Mar | K53: May | L53: Jul | M53: Oct | N53: Dic
B54: Noviembre | C54: 0 | D54: 175 | E54: =C54-D54 -> -175 | H54: CC | I54: 36000 | J54: 37000 | K54: 49000 | L54: 50000 | M54: 49000 | N54: 47350 | O54: =N54/$N$58 -> 0.73410853
B55: Diciembre | C55: 0 | D55: 25 | E55: =C55-D55 -> -25 | H55: SIAL | I55: 10000 | J55: 10075 | K55: --- | L55: --- | M55: --- | N55: --- | O55: ---
A56: 1992 | B56: Ene 92 | C56: 305 | D56: 125 | E56: =C56-D56 -> 180 | H56: PP | I56: 16000 | J56: 15750 | K56: 16400 | L56: 16375 | M56: 17000 | N56: 17250 | O56: =N56/$N$58 -> 0.26744186
B57: Febrero | C57: 0 | D57: 50 | E57: =C57-D57 -> -50
B58: Marzo | C58: 170 | D58: 245 | E58: =C58-D58 -> -75 | H58: TOTAL | I58: 62000 | J58: 62825 | K58: 65400 | L58: 66375 | M58: 66000 | N58: 64500
B59: Abril | C59: 270 | D59: 315 | E59: =C59-D59 -> -45 | H59: 2022
B60: Mayo | C60: 270 | D60: 150 | E60: =C60-D60 -> 120 | H60: Concepto | I60: Ene | J60: Mar | K60: May | L60: Jul | M60: Oct | N60: Dic
B61: Junio | C61: 270 | D61: 240 | E61: =C61-D61 -> 30 | H61: CC | I61: 48000 | J61: 41750 | K61: 50000 | L61: 50700 | M61: 47000 | N61: 46000 | O61: =N61/$N$65 -> 0.69355447
B62: Julio | C62: 450 | D62: 275 | E62: =C62-D62 -> 175 | H62: PP (1) | I62: 18115 | J62: 16450 | K62: 15000 | L62: 15000 | M62: 14750 | N62: 16550 | O62: =N62/$N$65 -> 0.24952884
B63: Agosto | C63: 1490 | D63: 695 | E63: =C63-D63 -> 795 | H63: INV (2) | I63: --- | J63: --- | K63: --- | L63: --- | M63: 3300 | N63: 3775 | O63: =N63/$N$65 -> 0.056916698
B64: Septiembre | C64: 0 | D64: 600 | E64: =C64-D64 -> -600
B65: Octubre | C65: 365 | D65: 775 | E65: =C65-D65 -> -410 | H65: TOTAL | I65: =SUM(I61:I63) -> 66115 | J65: =SUM(J61:J63) -> 58200 | K65: =SUM(K61:K63) -> 65000 | L65: =SUM(L61:L63) -> 65700 | M65: =SUM(M61:M63) -> 65050 | N65: =SUM(N61:N63) -> 66325
B66: Noviembre | C66: 365 | D66: 535 | E66: =C66-D66 -> -170 | H66: 2023
B67: Diciembre | C67: 365 | D67: 330 | E67: =C67-D67 -> 35 | H67: Concepto | I67: Ene | J67: Mar | K67: May | L67: Jul | M67: Oct | N67: Dic
A68: 1993 | B68: Ene 93 | C68: 365 | D68: 320 | E68: =C68-D68 -> 45 | H68: CC | I68: 47000 | J68: 37695 | K68: 42000 | L68: 41750 | M68: 41870 | N68: 39500 | O68: =N68/$N$72 -> 0.57163531
B69: Febrero | C69: 365 | D69: 300 | E69: =C69-D69 -> 65 | H69: PP (1) | I69: 16125 | J69: 16750 | K69: 16325 | L69: 17540 | M69: 17300 | N69: 18175 | O69: =N69/$N$72 -> 0.2630246
B70: Marzo | C70: 365 | D70: 365 | E70: =C70-D70 -> 0 | H70: INV (2) | I70: 4750 | J70: 5595 | K70: 7925 | L70: 8170 | M70: 10250 | N70: 11425 | O70: =N70/$N$72 -> 0.16534009
B71: Abril | C71: 365 | D71: 365 | E71: =C71-D71 -> 0
B72: Mayo | C72: 365 | D72: 345 | E72: =C72-D72 -> 20 | H72: TOTAL | I72: =SUM(I68:I70) -> 67875 | J72: =SUM(J68:J70) -> 60040 | K72: =SUM(K68:K70) -> 66250 | L72: =SUM(L68:L70) -> 67460 | M72: =SUM(M68:M70) -> 69420 | N72: =SUM(N68:N70) -> 69100
B73: Junio | C73: 1870 | D73: 195 | E73: =C73-D73 -> 1675
B74: Julio | C74: 365 | D74: 515 | E74: =C74-D74 -> -150 | H74: 2024
...

Sheet Ordenes
B4: Fecha | C4: Producto | D4: ISIN | E4: Bolsa | F4: Centro | G4: Número | H4: Precio | I4: Valor local | J4: Costes transac. | K4: Total
B20: 46113 | C20: ELECNOR | D20: ES0129743318 | E20: MAD | F20: XMAD | G20: 5 | H20: 34.9 | I20: =H20*G20 -> 174.5 | J20: -10.3 | K20: =-I20+J20 -> -184.8
B21: 46113 | C21: ACS | D21: ES0167050915 | E21: MAD | F21: XMAD | G21: 5 | H21: 112.35 | I21: =H21*G21 -> 561.75 | J21: -11 | K21: =-I21+J21 -> -572.75
B22: 46099 | C22: PFIZER | D22: US7170811035 | E22: XET | F22: XETB | G22: 5 | H22: 23.59 | I22: =H22*G22 -> 117.95 | J22: -3.9 | K22: =-I22+J22 -> -121.85
B23: 46099 | C23: ISHARES MSCI WOR D | D23: IE00B0M62Q58 | E23: EAM | F23: XAMS | G23: 5 | H23: 80.765 | I23: =H23*G23 -> 403.825 | J23: -3 | K23: =-I23+J23 -> -406.825
B24: 46099 | C24: ISHARES STOXX EUROPE 600 UCITS ETF (DE) | D24: DE0002635307 | E24: XET | F24: XETA | G24: 5 | H24: 59.18 | I24: =H24*G24 -> 295.9 | J24: -3 | K24: =-I24+J24 -> -298.9
B25: 46099 | C25: LTC PROPERTIES INC | D25: US5021751020 | E25: TDG | F25: XGAT | G25: 5 | H25: 33.64 | I25: =H25*G25 -> 168.2 | J25: -3.9 | K25: =-I25+J25 -> -172.1
B26: 46075 | C26: LOGISTA | D26: ES0105027009 | E26: MAD | F26: XMAD | G26: 5 | H26: 33.54 | I26: =H26*G26 -> 167.7 | J26: -10.3 | K26: =-I26+J26 -> -178
B27: 46065 | C27: Kraft Heinz Co | D27: US5007541064 | E27: TDG | F27: XGAT | G27: 5 | H27: 20.61 | I27: =H27*G27 -> 103.05 | J27: -3.9 | K27: =-I27+J27 -> -106.95
B28: 46046 | C28: ELECNOR | D28: ES0129743318 | E28: MAD | F28: XMAD | G28: 5 | H28: 25.9 | I28: =H28*G28 -> 129.5 | J28: -10.3 | K28: =-I28+J28 -> -139.8
B29: 46032 | C29: ISHARES PROP GLO | D29: IE00B1FZS350 | E29: EAM | F29: XAMS | G29: 5 | H29: 21.07 | I29: =H29*G29 -> 105.35 | J29: -3 | K29: =-I29+J29 -> -108.35 | L29: 2026 | M29: Año V
B30: 46032 | C30: DIAGEO | D30: GB0002374006 | E30: TDG | F30: XGAT | G30: 5 | H30: 19 | I30: =H30*G30 -> 95 | J30: -3.9 | K30: =-I30+J30 -> -98.9 | L30: =SUM(K6:K31) -> -2432.785 | M30: =SUM(I6:I31) -> 2322.725 | O30: comprobacion
B31: 46024 | C31: CUSTODIA DE VALORES | D31: ****** | E31: --- | F31: --- | G31: --- | H31: ---- | I31: --- | J31: -43.56 | K31: -43.56 | L31: Gasto | M31: Cartera | N31: =-L30-M30 -> 110.06 | O31: =SUM(J6:J31) -> -110.06
B32: 46012 | C32: LOGISTA | D32: ES0105027009 | E32: MAD | F32: XMAD | G32: 5 | H32: 29.66 | I32: =H32*G32 -> 148.3 | J32: -10.3 | K32: =-I32+J32 -> -158.6 | N32: Costes(comisiones)
B33: 45997 | C33: AT&T INC | D33: US00206R1023 | E33: TDG | F33: XGAT | G33: 5 | H33: 21.7 | I33: =H33*G33 -> 108.5 | J33: -3.9 | K33: =-I33+J33 -> -112.4
B34: 45997 | C34: ISHARES STOXX EUROPE 600 UCITS ETF (DE) | D34: DE0002635307 | E34: XET | F34: XETA | G34: 3 | H34: 57.48 | I34: =H34*G34 -> 172.44 | J34: -3 | K34: =-I34+J34 -> -175.44
B35: 45977 | C35: RED ELECTRICA | D35: ES0173093024 | E35: MAD | F35: XMAD | G35: 10 | H35: 15.08 | I35: =H35*G35 -> 150.8 | J35: -10.3 | K35: =-I35+J35 -> -161.1
B36: 45959 | C36: ISHARES STOXX EUROPE 600 UCITS ETF (DE) | D36: DE0002635307 | E36: XET | F36: XETA | G36: 2 | H36: 57.07 | I36: =H36*G36 -> 114.14 | J36: -3 | K36: =-I36+J36 -> -117.14
B37: 45959 | C37: COMCAST CORP | D37: US20030N1019 | E37: TDG | F37: XGAT | G37: 5 | H37: 24.705 | I37: =H37*G37 -> 123.525 | J37: -3.9 | K37: =-I37+J37 -> -127.425
B38: 45950 | C38: ENAGAS | D38: ES0130960018 | E38: MAD | F38: XMAD | G38: 10 | H38: 13.875 | I38: =H38*G38 -> 138.75 | J38: -10.3 | K38: =-I38+J38 -> -149.05
B39: 45932 | C39: INVESCO S&P 500 HIGH DIV LOW VOL UCITS ETF DIS | D39: IE00BWTN6Y99 | E39: XET | F39: XETA | G39: 5 | H39: 31.47 | I39: =H39*G39 -> 157.35 | J39: -3 | K39: =-I39+J39 -> -160.35
B40: 45931 | C40: PFIZER | D40: US7170811035 | E40: XET | F40: XETB | G40: 5 | H40: 21.9 | I40: =H40*G40 -> 109.5 | J40: -4.9 | K40: =-I40+J40 -> -114.4
B41: 45924 | C41: IBERDROLA | D41: ES0144580Y14 | E41: MAD | F41: XMAD | G41: 10 | H41: 15.64 | I41: =H41*G41 -> 156.4 | J41: -10.3 | K41: =-I41+J41 -> -166.7
B42: 45904 | C42: VERIZON COMMUNICATIONS INC | D42: US92343V1044 | E42: XET | F42: XETB | G42: 5 | H42: 37.68 | I42: =H42*G42 -> 188.4 | J42: -4.9 | K42: =-I42+J42 -> -193.3
B43: 45901 | C43: ISHARES PROP GLO | D43: IE00B1FZS350 | E43: EAM | F43: XAMS | G43: 5 | H43: 20.875 | I43: =H43*G43 -> 104.375 | J43: -1 | K43: =-I43+J43 -> -105.375
B44: 45901 | C44: SHELL PLC | D44: GB00BP6MXD84 | E44: EAM | F44: XAMS | G44: 5 | H44: 31.565 | I44: =H44*G44 -> 157.825 | J44: -4.9 | K44: =-I44+J44 -> -162.725
... B47: 45852 | C47: LOGISTA | D47: ES0105027009 | E47: MAD | F47: XMAD | G47: 5 | H47: 27.91 | I47: =H47*G47 -> 139.55 | J47: -10.3 | K47: =-I47+J47 -> -149.85
B48: 45839 | C48: CUSTODIA DE VALORES | D48: ****** | E48: --- | F48: --- | G48: --- | H48: ---- | I48: --- | J48: -43.56 | K48: -43.56
B49: 45835 | C49: INVESCO S&P 500 HIGH DIV LOW VOL UCITS ETF DIS | D49: IE00BWTN6Y99 | E49: XET | F49: XETA | G49: 5 | H49: 30 | I49: =H49*G49 -> 150 | J49: -3 | K49: =-I49+J49 -> -153
B50: 45835 | C50: LTC PROPERTIES INC | D50: US5021751020 | E50: TDG | F50: XGAT | G50: 5 | H50: 29.75 | I50: =H50*G50 -> 148.75 | J50: -3.9 | K50: =-I50+J50 -> -152.65
B51: 45820 | C51: RED ELECTRICA | D51: ES0173093024 | E51: MAD | F51: XMAD | G51: 10 | H51: 17.86 | I51: =H51*G51 -> 178.6 | J51: -10.36 | K51: =-I51+J51 -> -188.96
B52: 45794 | C52: ENAGAS | D52: ES0130960018 | E52: MAD | F52: XMAD | G52: 10 | H52: 13.445 | I52: =H52*G52 -> 134.45 | J52: -10.3 | K52: =-I52+J52 -> -144.75
B53: 45782 | C53: INVESCO S&P 500 HIGH DIV LOW VOL UCITS ETF DIS | D53: IE00BWTN6Y99 | E53: XET | F53: XETA | G53: 5 | H53: 31.5 | I53: =H53*G53 -> 157.5 | J53: -3 | K53: =-I53+J53 -> -160.5
B54: 45782 | C54: INTEL CORP | D54: US4581401001 | E54: TDG | F54: XGAT | G54: 5 | H54: 18 | I54: =H54*G54 -> 90 | J54: -3.9 | K54: =-I54+J54 -> -93.9
B55: 45782 | C55: DIAGEO | D55: GB0002374006 | E55: TDG | F55: XGAT | G55: 5 | H55: 25.215 | I55: =H55*G55 -> 126.075 | J55: -3.9 | K55: =-I55+J55 -> -129.975
B56: 45773 | C56: ISHARES PROP GLO | D56: IE00B1FZS350 | E56: EAM | F56: XAMS | G56: 5 | H56: 20.3 | I56: =H56*G56 -> 101.5 | J56: -1 | K56: =-I56+J56 -> -102.5
B57: 45773 | C57: UNILEVER | D57: GB00B10RZP78 | E57: EAM | F57: XAMS | G57: 5 | H57: 55 | I57: =H57*G57 -> 275 | J57: -4.9 | K57: =-I57+J57 -> -279.9
B58: 45771 | C58: IBERDROLA | D58: ES0144580Y14 | E58: MAD | F58: XMAD | G58: 10 | H58: 15.33 | I58: =H58*G58 -> 153.3 | J58: -10.3 | K58: =-I58+J58 -> -163.6
B59: 45743 | C59: ELECNOR | D59: ES0129743318 | E59: MAD | F59: XMAD | G59: 10 | H59: 17.62 | I59: =H59*G59 -> 176.2 | J59: -10 | K59: =-I59+J59 -> -186.2
B60: 45741 | C60: INVESCO S&P 500 HIGH DIV LOW VOL UCITS ETF DIS | D60: IE00BWTN6Y99 | E60: XET | F60: XETA | G60: 5 | H60: 34.5 | I60: =H60*G60 -> 172.5 | J60: -3 | K60: =-I60+J60 -> -175.5
...

Sheet Inversiones
C3: Google Finance
C4: Yahoo Finanzas
C8: CARTERA DE INVERSION | P8: Symbol | Q8: Title | S8: Shares | T8: Precio actual | U8: Total | V8: Dividend | W8: % | X8: % | AB8: ESTIMACIONES ANUALES (por acción)
O9: ETFs y PP | AE9: ENE | AF9: FEB | AG9: MAR | AH9: ABR | AI9: MAY | AJ9: JUN | AK9: JUL | AL9: AGO | AM9: SEP | AN9: OCT | AO9: NOV | AP9: DIC
C10: ETF/FONDO | D10: TÍTULO | J10: SIMBOL | K10: % | M10: EUR | N10: 1 | P10: Novartis PPE | Q10: SANTANDER PPE | S10: 63 | T10: 120 | U10: =S10*T10 -> 7560 | V10: NO | W10: =U10/$R$45 -> #VALUE! | AC10: HDLV.DE | AD10: #VALUE! | AG10: Xxx | AJ10: Xxx | AM10: Xxx | AP10: Xxx
C11: BBVA FS | D11: Futuro:bono Nocional Usa 10 Años Física | J11: N/A | K11: 10.09% | M11: EUR | N11: 2 | P11: 0P0000RYC6.F | Q11: CAIXABANK Tendencias PP | S11: 607.4 | T11: 33 | U11: =S11*T11 -> 20044.2 | V11: NO | W11: =U11/$R$45 -> #VALUE! | AC11: IWDP.AS | AD11: #VALUE! | AI11: 0.165 | AO11: 0.166
C12: BBVA FS | D12: Futuro:bono Nocional Aleman 10 Años Física | J12: N/A | K12: 8.10% | M12: EUR | N12: 3 | P12: 0P00000VSG.F | Q12: #VALUE! | S12: 7.3 | T12: 973.8 | U12: =S12*T12 -> 7108.74 | V12: NO | W12: =U12/$R$45 -> #VALUE! | AC12: EXSA.DE | AD12: #VALUE! | AG12: Xxx | AJ12: Xxx | AM12: Xxx | AP12: Xxx
C13: BBVA FS | D13: Xtrackers MSCI World ETF 1C | J13: XDWD.IR | K13: 5.62% | M13: {=_FV(Q13,"Currency",TRUE)} -> #VALUE! | N13: 4 | P13: HDLV.DE | Q13: #VALUE! | S13: 55 | T13: {=_FV(Q13,"Price")} -> #VALUE! | U13: =S13*T13 -> #VALUE! | V13: YES | W13: =U13/$R$45 -> #VALUE! | AC13: IWRD.AS | AD13: #VALUE! | AG13: 0.14 | AJ13: 0.14 | AM13: 0.14 | AP13: 0.14
C14: BBVA FS | D14: iShares Core MSCI World ETF USD Acc | J14: IWDA | K14: 5.62% | M14: {=_FV(Q14,"Currency",TRUE)} -> #VALUE! | N14: 5 | P14: IWDP.AS | Q14: #VALUE! | S14: 60 | T14: {=_FV(Q14,"Price")} -> #VALUE! | U14: =S14*T14 -> #VALUE! | V14: YES | W14: =U14/$R$45 -> #VALUE! | AC14: {=_FV(AD14,"Ticker symbol",TRUE)} -> #VALUE! | AD14: #VALUE! | AJ14: 0.27 | AP14: 0.06
C15: BBVA FS | D15: Amundi MSCI Wld Climt Trnstn CTB ETFDR € | J15: LWCR.IR | K15: 4.47% | M15: {=_FV(Q15,"Currency",TRUE)} -> #VALUE! | N15: 6 | P15: IWRD.AS | Q15: #VALUE! | S15: 25 | T15: {=_FV(Q15,"Price")} -> #VALUE! | U15: =S15*T15 -> #VALUE! | V15: YES | W15: =U15/$R$45 -> #VALUE! | AC15: {=_FV(AD15,"Ticker symbol",TRUE)} -> #VALUE! | AD15: #VALUE! | AF15: 0.4 | AL15: 0.8
C16: BBVA FS | D16: Futuro:msci World Nr | J16: N/A | K16: 4.45% | M16: {=_FV(Q16,"Currency",TRUE)} -> #VALUE! | N16: 7 | P16: EXSA.DE | Q16: #VALUE! | S16: 35 | T16: {=_FV(Q16,"Price")} -> #VALUE! | U16: =S16*T16 -> #VALUE! | V16: YES | W16: =U16/$R$45 -> #VALUE! | AC16: {=_FV(AD16,"Ticker symbol",TRUE)} -> #VALUE! | AD16: #VALUE! | AK16: 0.7 | AP16: 1
C17: BBVA FS | D17: Xtrackers MSCI WORLD ESG ETF 1C | J17: XZW0 | K17: 3.54% | AC17: {=_FV(AD17,"Ticker symbol",TRUE)} -> #VALUE! | AD17: #VALUE!
C18: BBVA FS | D18: iShares JP Morgan $ EM Bd ETF USD Acc | J18: JPEA | K18: 3.50% | T18: Total ETFs, Fondos y Planes | U18: =SUM(U10:U17) -> #VALUE! | X18: =U18/$R$45 -> #VALUE! | AC18: {=_FV(AD18,"Ticker symbol",TRUE)} -> #VALUE! | AD18: #VALUE! | AE18: 0.29 | AK18: 0.29
C19: BBVA FS | D19: BNPP Insticash EUR 1D ST VNAV I Cap | J19: N/A | K19: 3.48% | O19: ACCIONES | AC19: {=_FV(AD19,"Ticker symbol",TRUE)} -> #VALUE! | AD19: #VALUE! | AE19: 0.27 | AJ19: 0.72
C20: BBVA FS | D20: FONDO:BETAMINER BEHEDGED | J20: N/A | K20: 2.45% | AC20: {=_FV(AD20,"Ticker symbol",TRUE)} -> #VALUE! | AD20: #VALUE! | AF20: 0.45 | AK20: 1.45
C21: CABK | D21: CS (Lux) Digital Health Equity IB USD | J21: N/A | K21: 6.40% | M21: {=_FV(Q21,"Currency",TRUE)} -> #VALUE! | N21: 1 | P21: {=_FV(Q21,"Ticker symbol",TRUE)} -> #VALUE! | Q21: #VALUE! | S21: 45 | T21: {=_FV(Q21,"Price")} -> #VALUE! | U21: =S21*T21 -> #VALUE! | V21: YES | W21: =U21/$R$45 -> #VALUE! | X21: ELECNOR | AC21: {=_FV(AD21,"Ticker symbol",TRUE)} -> #VALUE! | AD21: #VALUE! | AF21: 0.28 | AI21: 0.28 | AL21: 0.28 | AO21: 0.28
C22: CABK | D22: Invesco Glbl Consmr Trnds C USD Acc | J22: N/A | K22: 5.94% | M22: {=_FV(Q22,"Currency",TRUE)} -> #VALUE! | N22: 2 | P22: {=_FV(Q22,"Ticker symbol",TRUE)} -> #VALUE! | Q22: #VALUE! | S22: 50 | T22: {=_FV(Q22,"Price")} -> #VALUE! | U22: =S22*T22 -> #VALUE! | V22: YES | W22: =U22/$R$45 -> #VALUE! | X22: LOGISTA | AC22: {=_FV(AD22,"Ticker symbol",TRUE)} -> #VALUE! | AD22: #VALUE! | AE22: 0.087 | AH22: 0.087 | AK22: 0.087 | AN22: 0.087
C23: CABK | D23: RobecoSAM Smart Materials Eqs I EUR | J23: N/A | K23: 4.44% | M23: {=_FV(Q23,"Currency",TRUE)} -> #VALUE! | N23: 3 | P23: {=_FV(Q23,"Ticker symbol",TRUE)} -> #VALUE! | Q23: #VALUE! | S23: 50 | T23: {=_FV(Q23,"Price")} -> #VALUE! | U23: =S23*T23 -> #VALUE! | V23: YES | W23: =U23/$R$45 -> #VALUE! | X23: ENAGAS | AC23: {=_FV(AD23,"Ticker symbol",TRUE)} -> #VALUE! | AD23: #VALUE! | AG23: 0.125 | AJ23: 0.125 | AM23: 0.125 | AP23: 0.125
C24: CABK | D24: Pictet - Robotics I EUR | J24: N/A | K24: 4.41% | M24: {=_FV(Q24,"Currency",TRUE)} -> #VALUE! | N24: 4 | P24: {=_FV(Q24,"Ticker symbol",TRUE)} -> #VALUE! | Q24: #VALUE! | S24: 0 | T24: {=_FV(Q24,"Price")} -> #VALUE! | U24: =S24*T24 -> #VALUE! | V24: NO | W24: =U24/$R$45 -> #VALUE! | AC24: {=_FV(AD24,"Ticker symbol",TRUE)} -> #VALUE! | AD24: #VALUE! | AG24: 0.4 | AJ24: 0.4 | AM24: 0.4 | AP24: 0.4
C25: CABK | D25: JPM Global Natural Resources C (acc) USD | J25: N/A | K25: 4.04% | M25: {=_FV(Q25,"Currency",TRUE)} -> #VALUE! | N25: 5 | P25: {=_FV(Q25,"Ticker symbol",TRUE)} -> #VALUE! | Q25: #VALUE! | S25: 50 | T25: {=_FV(Q25,"Price")} -> #VALUE! | U25: =S25*T25 -> #VALUE! | V25: YES | W25: =U25/$R$45 -> #VALUE! | X25: REDEIA | AC25: {=_FV(AD25,"Ticker symbol",TRUE)} -> #VALUE! | AD25: #VALUE!
C26: CABK | D26: BGF Sustainable Energy A2 | J26: N/A | K26: 3.91% | M26: {=_FV(Q26,"Currency",TRUE)} -> #VALUE! | N26: 6 | P26: {=_FV(Q26,"Ticker symbol",TRUE)} -> #VALUE! | Q26: #VALUE! | S26: 51 | T26: {=_FV(Q26,"Price")} -> #VALUE! | U26: =S26*T26 -> #VALUE! | V26: YES | W26: =U26/$R$45 -> #VALUE! | X26: IBERDROLA | AC26: {=_FV(AD26,"Ticker symbol",TRUE)} -> #VALUE! | AD26: #VALUE! | AE26: 0.19 | AF26: 0.19 | AG26: 0.19 | AH26: 0.19 | AI26: 0.19 | AJ26: 0.19 | AK26: 0.19 | AL26: 0.19 | AM26: 0.19 | AN26: 0.19 | AO26: 0.19 | AP26: 0.19
C27: CABK | D27: Nordea 1 - Global Climate & Envir BI EUR | J27: N/A | K27: 3.91% | M27: {=_FV(Q27,"Currency",TRUE)} -> #VALUE! | N27: 7 | P27: {=_FV(Q27,"Ticker symbol",TRUE)} -> #VALUE! | Q27: #VALUE! | S27: 30 | T27: {=_FV(Q27,"Price")} -> #VALUE! | U27: =S27*T27 -> #VALUE! | V27: YES | W27: =U27/$R$45 -> #VALUE! | X27: ACS | AC27: {=_FV(AD27,"Ticker symbol",TRUE)} -> #VALUE! | AD27: #VALUE! | AG27: 0.31 | AJ27: 0.33 | AM27: 0.33 | AP27: 0.33
C28: CABK | D28: Robeco New World Financials I $ | J28: N/A | K28: 3.91% | M28: {=_FV(Q28,"Currency",TRUE)} -> #VALUE! | N28: 8 | P28: {=_FV(Q28,"Ticker symbol",TRUE)} -> #VALUE! | Q28: #VALUE! | S28: 25 | T28: {=_FV(Q28,"Price")} -> #VALUE! | U28: =S28*T28 -> #VALUE! | V28: YES | W28: =U28/$R$45 -> #VALUE! | X28: ATT | AC28: {=_FV(AD28,"Ticker symbol",TRUE)} -> #VALUE! | AD28: #VALUE! | AG28: 0.36 | AJ28: 0.37 | AM28: 0.37 | AO28: 0.37
C29: CABK | D29: BNP Paribas Aqua I C | J29: N/A | K29: 3.72% | M29: {=_FV(Q29,"Currency",TRUE)} -> #VALUE! | N29: 9 | P29: {=_FV(Q29,"Ticker symbol",TRUE)} -> #VALUE! | Q29: #VALUE! | S29: 20 | T29: {=_FV(Q29,"Price")} -> #VALUE! | U29: =S29*T29 -> #VALUE! | V29: YES | W29: =U29/$R$45 -> #VALUE! | X29: INTEL | AC29: {=_FV(AD29,"Ticker symbol",TRUE)} -> #VALUE! | AD29: #VALUE! | AE29: 0.66 | AH29: 0.66 | AK29: 0.66 | AN29: 0.66
C30: CABK | D30: Franklin Technology I Acc EUR | J30: N/A | K30: 3.71% | M30: {=_FV(Q30,"Currency",TRUE)} -> #VALUE! | N30: 10 | P30: {=_FV(Q30,"Ticker symbol",TRUE)} -> #VALUE! | Q30: #VALUE! | S30: 25 | T30: {=_FV(Q30,"Price")} -> #VALUE! | U30: =S30*T30 -> #VALUE! | V30: YES | W30: =U30/$R$45 -> #VALUE! | X30: KRAFT | AC30: {=_FV(AD30,"Ticker symbol",TRUE)} -> #VALUE! | AD30: #VALUE! | AF30: 0.48 | AI30: 0.48 | AL30: 0.48 | AO30: 0.48
C31: EXSA | D31: #VALUE! | J31: NESN | K31: 3.02% | M31: {=_FV(Q31,"Currency",TRUE)} -> #VALUE! | N31: 11 | P31: {=_FV(Q31,"Ticker symbol",TRUE)} -> #VALUE! | Q31: #VALUE! | S31: 20 | T31: {=_FV(Q31,"Price")} -> #VALUE! | U31: =S31*T31 -> #VALUE! | V31: YES | W31: =U31/$R$45 -> #VALUE! | X31: LTC
C32: EXSA | D32: #VALUE! | J32: ASML | K32: 2.42% | M32: {=_FV(Q32,"Currency",TRUE)} -> #VALUE! | N32: 12 | P32: {=_FV(Q32,"Ticker symbol",TRUE)} -> #VALUE! | Q32: #VALUE! | S32: 25 | T32: {=_FV(Q32,"Price")} -> #VALUE! | U32: =S32*T32 -> #VALUE! | V32: YES | W32: =U32/$R$45 -> #VALUE! | X32: DIAGEO | AD32: Total mes /accion | AE32: =SUM(AE10:AE31) -> 1.497 | AF32: =SUM(AF10:AF31) -> 1.8 | AG32: =SUM(AG10:AG31) -> 1.525 | AH32: =SUM(AH10:AH31) -> 0.937 | AI32: =SUM(AI10:AI31) -> 1.115 | AJ32: =SUM(AJ10:AJ31) -> 2.545 | AK32: =SUM(AK10:AK31) -> 3.377 | AL32: =SUM(AL10:AL31) -> 1.75 | ... AP32: =SUM(AP10:AP31) -> 2.245
C33: EXSA | D33: #VALUE! | J33: ROG | K33: 2.23% | M33: {=_FV(Q33,"Currency",TRUE)} -> #VALUE! | N33: 13 | P33: {=_FV(Q33,"Ticker symbol",TRUE)} -> #VALUE! | Q33: #VALUE! | S33: 20 | T33: {=_FV(Q33,"Price")} -> #VALUE! | U33: =S33*T33 -> #VALUE! | V33: YES | W33: =U33/$R$45 -> #VALUE! | X33: SHELL | AB33: Total / accion | AD33: =SUM(AE32:AP32) -> 20.769
C34: EXSA | D34: #VALUE! | J34: NOVN | K34: 1.89% | M34: {=_FV(Q34,"Currency",TRUE)} -> #VALUE! | N34: 14 | P34: {=_FV(Q34,"Ticker symbol",TRUE)} -> #VALUE! | Q34: #VALUE! | S34: 17 | T34: {=_FV(Q34,"Price")} -> #VALUE! | U34: =S34*T34 -> #VALUE! | V34: YES | W34: =U34/$R$45 -> #VALUE! | X34: UNILEVER
C35: EXSA | D35: #VALUE! | J35: MC.PA | K35: 1.75% | M35: {=_FV(Q35,"Currency",TRUE)} -> #VALUE! | N35: 15 | P35: {=_FV(Q35,"Ticker symbol",TRUE)} -> #VALUE! | Q35: #VALUE! | S35: 25 | T35: {=_FV(Q35,"Price")} -> #VALUE! | U35: =S35*T35 -> #VALUE! | V35: YES | W35: =U35/$R$45 -> #VALUE! | X35: VERIZON
C36: EXSA | D36: #VALUE! | J36: AZN.L | K36: 1.32% | M36: {=_FV(Q36,"Currency",TRUE)} -> #VALUE! | N36: 16 | P36: {=_FV(Q36,"Ticker symbol",TRUE)} -> #VALUE! | Q36: #VALUE! | S36: 0 | T36: {=_FV(Q36,"Price")} -> #VALUE! | U36: =S36*T36 -> #VALUE! | V36: NO | W36: =U36/$R$45 -> #VALUE!
C37: EXSA | D37: #VALUE! | J37: SAP.DE | K37: 1.29% | M37: {=_FV(Q37,"Currency",TRUE)} -> #VALUE! | N37: 17 | P37: {=_FV(Q37,"Ticker symbol",TRUE)} -> #VALUE! | Q37: #VALUE! | S37: 25 | T37: {=_FV(Q37,"Price")} -> #VALUE! | U37: =S37*T37 -> #VALUE! | V37: YES | W37: =U37/$R$45 -> #VALUE! | X37: COMCAST
C38: EXSA | D38: #VALUE! | J38: ULVR.L | K38: 1.29% | M38: EUR | N38: 18 | P38: PFE | Q38: #VALUE! | S38: 20 | T38: {=_FV(Q38,"Price")} -> #VALUE! | U38: =S38*T38 -> #VALUE! | V38: YES | W38: =U38/$R$45 -> #VALUE! | X38: PFIZER
C39: EXSA | D39: #VALUE! | J39: LIN.L | K39: 1.26%
C40: EXSA | D40: #VALUE! | J40: NOVO B | K40: 1.17% | W40: =SUM(W10:W38) -> #VALUE!
C41: HDLV | D41: #VALUE! | J41: IRM | K41: 3.69% | T41: Total Acciones | U41: =SUM(U21:U40) -> #VALUE! | X41: =U41/$R$45 -> #VALUE!
C42: HDLV | D42: #VALUE! | J42: XOM | K42: 3.50%
C43: HDLV | D43: #VALUE! | J43: LUMN | K43: 3.20% | Q43: Total Posiciones | R43: =COUNTA(S9:S40) -> 25
C44: HDLV | D44: #VALUE! | J44: KMI | K44: 3.13% | Q44: Total Shares | R44: =SUM(S10:S40) -> 1350.7
C45: HDLV | D45: #VALUE! | J45: MO | K45: 3.00% | Q45: Total invertido | R45: =U18+U41 -> #VALUE!
...

Sheet Dividendo
C3: Cartera de Inversion (2022 - 2026)
D6: Symbol | E6: Title | G6: Broker | H6: Shares | I6: Avg Cost / Share | J6: Total | K6: Dividend/accion | L6: En cartera | M6: Favorito | N6: Fecha entrada | O6: 2023 | P6: 2024 | Q6: 2025 | R6: 2026
C8: 1 | D8: {=_FV(E8,"Ticker symbol",TRUE)} -> #VALUE! | E8: #VALUE! | F8: Contruct&Engin | G8: CaixaBank | H8: 30 | I8: {=_FV(E8,"Price")} -> #VALUE! | J8: =H8*I8 -> #VALUE! | K8: 1 | L8: =IF(H8>0,"YES","NO") -> YES | M8: 1 | N8: 45200 | P8: =G94 -> 1.43 | Q8: =G126 -> 37.42 | R8: =G156 -> 9.45 | S8: #VALUE!
C9: 2 | D9: {=_FV(E9,"Ticker symbol",TRUE)} -> #VALUE! | E9: #VALUE! | F9: Telecommunic | G9: DeGiro | H9: 25 | I9: {=_FV(E9,"Price")} -> #VALUE! | J9: =H9*I9 -> #VALUE! | K9: 0.28 | L9: =IF(H9>0,"YES","NO") -> YES | M9: 1 | N9: 44986 | O9: =G48 -> 5.66 | P9: =G79 -> 9.17 | Q9: =G110 -> 11.14 | R9: =G140 -> 4.86 | S9: #VALUE!
C10: 3 | D10: {=_FV(E10,"Ticker symbol",TRUE)} -> #VALUE! | E10: #VALUE! | F10: Telecommunic | G10: DeGiro | H10: 25 | I10: {=_FV(E10,"Price")} -> #VALUE! | J10: =H10*I10 -> #VALUE! | K10: 0.29 | L10: =IF(H10>0,"YES","NO") -> YES | M10: 1 | N10: 45017 | O10: =SUM(H56:V56) -> 5.89 | P10: =G87 -> 9.98 | Q10: =G118 -> 14.08 | R10: =G148 -> 5.77 | S10: #VALUE!
C11: 4 | D11: {=_FV(E11,"Ticker symbol",TRUE)} -> #VALUE! | E11: #VALUE! | F11: Contruct&Engin | G11: CaixaBank | H11: 45 | I11: {=_FV(E11,"Price")} -> #VALUE! | J11: =H11*I11 -> #VALUE! | K11: 1.6 | L11: =IF(H11>0,"YES","NO") -> YES | M11: 1 | N11: 44986 | O11: =SUM(H57:V57) -> 1.8 | P11: =G89 -> 158.97 | Q11: =G121 -> 102 | R11: =G151 -> 0 | S11: #VALUE!
C12: 5 | D12: LOG | E12: #VALUE! | F12: Logistics | G12: CaixaBank | H12: 50 | I12: {=_FV(E12,"Price")} -> #VALUE! | J12: =H12*I12 -> #VALUE! | K12: 1.4 | L12: =IF(H12>0,"YES","NO") -> YES | M12: 1 | N12: 44986 | O12: =SUM(H59:V59) -> 2.76 | P12: =G91 -> 28.68 | Q12: =G123 -> 52.9 | R12: =G153 -> 60.75 | S12: #VALUE!
C13: 6 | D13: {=_FV(E13,"Ticker symbol",TRUE)} -> #VALUE! | E13: #VALUE! | F13: Oil&Gas | G13: CaixaBank | H13: 50 | I13: {=_FV(E13,"Price")} -> #VALUE! | J13: =H13*I13 -> #VALUE! | K13: 1.25 | L13: =IF(H13>0,"YES","NO") -> YES | M13: 1 | N13: 44986 | O13: =SUM(H58:V58) -> 14.4 | P13: =G90 -> 32.66 | Q13: =G122 -> 33 | R13: =G152 -> 0 | S13: #VALUE!
C14: 7 | D14: {=_FV(E14,"Ticker symbol",TRUE)} -> #VALUE! | E14: #VALUE! | F14: Electrical | G14: CaixaBank | H14: 51 | I14: {=_FV(E14,"Price")} -> #VALUE! | J14: =H14*I14 -> #VALUE! | K14: 0.32 | L14: =IF(H14>0,"YES","NO") -> YES | M14: 1 | N14: 45108 | O14: =SUM(H61:V61) -> 0 | P14: =G93 -> 1.13 | Q14: =G125 -> 3.51 | R14: =G155 -> 8.38 | S14: #VALUE!
